{"name": "log into account", "status": "failed", "statusDetails": {"message": "AssertionError\n", "trace": "  File \"/home/zeufack/Documents/programming/python/test_carrefour/lib/python3.7/site-packages/behave/model.py\", line 1329, in run\n    match.run(runner.context)\n  File \"/home/zeufack/Documents/programming/python/test_carrefour/lib/python3.7/site-packages/behave/matchers.py\", line 98, in run\n    self.func(context, *args, **kwargs)\n  File \"features/steps/connexion_error_msg.py\", line 20, in step_impl\n    assert con_error_msg != 'Error 16'\n"}, "steps": [{"name": "Given navigate to carrefour web site", "status": "passed", "start": 1620212980039, "stop": 1620212990797}, {"name": "When try to connet", "status": "passed", "start": 1620212990798, "stop": 1620212993628}, {"name": "Then the error message should be clear", "status": "failed", "statusDetails": {"message": "AssertionError\n", "trace": "  File \"/home/zeufack/Documents/programming/python/test_carrefour/lib/python3.7/site-packages/behave/model.py\", line 1329, in run\n    match.run(runner.context)\n  File \"/home/zeufack/Documents/programming/python/test_carrefour/lib/python3.7/site-packages/behave/matchers.py\", line 98, in run\n    self.func(context, *args, **kwargs)\n  File \"features/steps/connexion_error_msg.py\", line 20, in step_impl\n    assert con_error_msg != 'Error 16'\n"}, "start": 1620212993628, "stop": 1620212993684}], "start": 1620212980038, "stop": 1620212993685, "uuid": "a5885cc1-5cc7-424e-a7a8-cbc05c056727", "historyId": "eeec90e572d69ad6af98a18fba74b356", "fullName": "Connexion Error: log into account", "labels": [{"name": "severity", "value": "normal"}, {"name": "tag", "value": "chrome"}, {"name": "feature", "value": "Connexion Error"}, {"name": "framework", "value": "behave"}, {"name": "language", "value": "cpython3"}]}